Workbook

Sheet Financial Dashboard
A1: Personal Wealth Notebook
A2: NYC earnings, taxes, savings, account-bucket growth, and house-aware retirement planning in one visible model. Use the selected-year input on Model Inputs and hover chart markers in Excel for point values.
A4: Working Years Entered | E4: Baseline Retirement Spend | I4: Base Liquid After Close | M4: Base All-In Draw Rate
A5: ='Savings Projection'!$B$12 -> 10 | E5: ='Savings Projection'!$B$13 -> 200000 | I5: ='Scenario Lab'!$H$14 -> 3736659.2 | M5: ='Scenario Lab'!$H$18 -> 0.13878238
A8: Ending Taxable | D8: Ending 401(k) | G8: Ending Roth | J8: Ending HSA | M8: Ending Total Wealth @ Base
A9: ='Savings Projection'!$AE$58 -> 18697878 | D9: ='Savings Projection'!$AF$58 -> 1854742.6 | G9: ='Savings Projection'!$AG$58 -> 567778.35 | J9: ='Savings Projection'!$AH$58 -> 0 | M9: ='Savings Projection'!$AI$58 -> 21120399
A13: Wealth Path Through Work And Retirement ($mm)
A33: Wealth By Account @ Base Return ($mm) | I33: Savings vs. Retirement Draws ($mm)
A55: Ending Wealth Mix @ Base Return | G55: Base House + Retirement
A56: Taxable | B56: ='Savings Projection'!$AE$58 -> 18697878 | C56: =IF($B$60=0,0,B56/$B$60) -> 0.88529947 | G56: Baseline retirement spend | M56: ='Scenario Lab'!$H$8 -> 200000
A57: 401(k) | B57: ='Savings Projection'!$AF$58 -> 1854742.6 | C57: =IF($B$60=0,0,B57/$B$60) -> 0.087817593 | G57: Liquid wealth after close | M57: ='Scenario Lab'!$H$14 -> 3736659.2
A58: Roth | B58: ='Savings Projection'!$AG$58 -> 567778.35 | C58: =IF($B$60=0,0,B58/$B$60) -> 0.026882937 | G58: Annual housing carry (all recurring housing costs) | M58: ='Scenario Lab'!$H$15 -> 318582.45
A59: HSA | B59: ='Savings Projection'!$AH$58 -> 0 | C59: =IF($B$60=0,0,B59/$B$60) -> 0 | G59: Total retirement need | M59: ='Scenario Lab'!$H$16 -> 518582.45
A60: Total | B60: =SUM(B56:B59) -> 21120399 | G60: All-in draw rate | M60: ='Scenario Lab'!$H$18 -> 0.13878238
G61: Max non-housing spend @ target draw | M61: ='Scenario Lab'!$H$19 -> 0
G62: Planning max house by draw / carry rules | M62: ='Scenario Lab'!$H$22 -> 1690179.6
G64: Selected Year Snapshot
G65: Selected year | J65: =MAX(1,MIN(ROUND('Model Inputs'!$B$15,0),ROWS('Savings Projection'!$A$19:$A$58))) -> 10 | L65: Phase | O65: =INDEX('Savings Projection'!$C$19:$C$58,MAX(1,MIN(ROUND('Model Inputs'!$B$15,0),ROWS('Savings Projection'!$A$19:$A$58)))) -> Working
G66: Gross comp | J66: =INDEX('Savings Projection'!$B$19:$B$58,MAX(1,MIN(ROUND('Model Inputs'!$B$15,0),ROWS('Savings Projection'!$A$19:$A$58)))) -> 2595495.8 | L66: Total tax / deductions | O66: =INDEX('Savings Projection'!$Q$19:$Q$58,MAX(1,MIN(ROUND('Model Inputs'!$B$15,0),ROWS('Savings Projection'!$A$19:$A$58)))) -> 1286105
G67: Wealth @ 0% | J67: =INDEX('Savings Projection'!$AJ$19:$AJ$58,MAX(1,MIN(ROUND('Model Inputs'!$B$15,0),ROWS('Savings Projection'!$A$19:$A$58)))) -> 5317592.2 | L67: Wealth @ Base | O67: =INDEX('Savings Projection'!$AI$19:$AI$58,MAX(1,MIN(ROUND('Model Inputs'!$B$15,0),ROWS('Savings Projection'!$A$19:$A$58)))) -> 6430241.6
G68: Wealth @ 8% | J68: =INDEX('Savings Projection'!$AK$19:$AK$58,MAX(1,MIN(ROUND('Model Inputs'!$B$15,0),ROWS('Savings Projection'!$A$19:$A$58)))) -> 6876892.3 | L68: Taxable balance | O68: =INDEX('Savings Projection'!$AE$19:$AE$58,MAX(1,MIN(ROUND('Model Inputs'!$B$15,0),ROWS('Savings Projection'!$A$19:$A$58)))) -> 6008456.2
G69: Total annual savings | J69: =INDEX('Savings Projection'!$X$19:$X$58,MAX(1,MIN(ROUND('Model Inputs'!$B$15,0),ROWS('Savings Projection'!$A$19:$A$58)))) -> 1139770.3 | L69: Actual withdrawal | O69: =INDEX('Savings Projection'!$Z$19:$Z$58,MAX(1,MIN(ROUND('Model Inputs'!$B$15,0),ROWS('Savings Projection'!$A$19:$A$58)))) -> 0
A70: Scenario Comparison
A71: Metric | B71: Downside | C71: Base | D71: Upside | F71: Scenario Liquid Wealth Comparison ($mm)
A72: Gross comp multiplier | B72: ='Scenario Lab'!G6 -> 0.75 | C72: ='Scenario Lab'!H6 -> 1 | D72: ='Scenario Lab'!I6 -> 1.2
A73: Return assumption | B73: ='Scenario Lab'!G7 -> 0.04 | C73: ='Scenario Lab'!H7 -> 0.06 | D73: ='Scenario Lab'!I7 -> 0.09
A74: Baseline retirement spend | B74: ='Scenario Lab'!G8 -> 170000 | C74: ='Scenario Lab'!H8 -> 200000 | D74: ='Scenario Lab'!I8 -> 240000
A75: Home purchase price | B75: ='Scenario Lab'!G10 -> 5000000 | C75: ='Scenario Lab'!H10 -> 5000000 | D75: ='Scenario Lab'!I10 -> 5000000
A76: Cash required at close | B76: ='Scenario Lab'!G11 -> 2025000 | C76: ='Scenario Lab'!H11 -> 2375000 | D76: ='Scenario Lab'!I11 -> 2125000
A77: Liquid wealth after close | B77: ='Scenario Lab'!G14 -> 1797689.5 | C77: ='Scenario Lab'!H14 -> 3736659.2 | D77: ='Scenario Lab'!I14 -> 4726250.9
A78: Annual housing carry at retirement | B78: ='Scenario Lab'!G15 -> 345129.3 | C78: ='Scenario Lab'!H15 -> 318582.45 | D78: ='Scenario Lab'!I15 -> 0
A79: Total retirement need | B79: ='Scenario Lab'!G16 -> 515129.3 | C79: ='Scenario Lab'!H16 -> 518582.45 | D79: ='Scenario Lab'!I16 -> 240000
A80: All-in draw rate at retirement | B80: ='Scenario Lab'!G18 -> 0.28655077 | C80: ='Scenario Lab'!H18 -> 0.13878238 | D80: ='Scenario Lab'!I18 -> 0.035214323
A81: Max non-housing spend @ target draw | B81: ='Scenario Lab'!G19 -> 0 | C81: ='Scenario Lab'!H19 -> 0 | D81: ='Scenario Lab'!I19 -> 238539.3
A82: Planning max house price | B82: ='Scenario Lab'!G22 -> 1326147.3 | C82: ='Scenario Lab'!H22 -> 1690179.6 | D82: ='Scenario Lab'!I22 -> 1914277.6
A83: Retired years funded | B83: ='Scenario Lab'!G23 -> 3 | C83: ='Scenario Lab'!H23 -> 9 | D83: ='Scenario Lab'!I23 -> 15
A84: First shortfall year | B84: ='Scenario Lab'!G24 -> 14 | C84: ='Scenario Lab'!H24 -> 20 | D84: ='Scenario Lab'!I24 -> 25
A85: Planning max house uses purchase-year liquidity for the close and retirement-year draw / carry rules for sustainability. | B85: ='Scenario Lab'!G25 -> 0 | C85: ='Scenario Lab'!H25 -> 0 | D85: ='Scenario Lab'!I25 -> 0
A86: Base Sensitivity Frontier | I86: How To Read It
A87: Reference-case liquidity margin | F87: ='Scenario Lab'!$N$217 -> 4519714 | I87: The frontier is centered on the smaller of your current target house and the base planning max house. Planning max house is not your close-funding limit; it is the tighter of the liquidity-floor cap and the annual housing-budget cap under the draw-rate rules.
...

Sheet Model Inputs
A1: Model Inputs
A2: Edit global assumptions and scenario parameters here. Year-by-year compensation, HSA, after-tax payroll, rent, and living costs now live visibly on Savings Projection.
A4: Base Inputs | E4: Scenario, Retirement, And House Inputs | J4: Baseline retirement spend excludes house-related costs. Housing carry means the recurring housing cash costs that sit on top of that baseline spend: mortgage payments, property tax, insurance, maintenance, HOA / common charges, and home services / utilities. One-time purchase cash and move / furnish reserve are modeled separately.
A5: Filing status | B5: Single | E5: Scenario | F5: Downside | G5: Base | H5: Upside
A6: Resident city | B6: New York City | E6: Gross comp multiplier | F6: 0.75 | G6: 1 | H6: 1.2
A7: Starting taxable assets | B7: 150000 | E7: Tax multiplier | F7: 1.04 | G7: 1 | H7: 0.97
A8: Starting 401(k) balance | B8: 0 | E8: Rent multiplier | F8: 1 | G8: 1 | H8: 1.05
A9: Starting Roth balance | B9: 0 | E9: Living multiplier | F9: 0.95 | G9: 1 | H9: 1.08
A10: Starting HSA balance | B10: 0 | E10: Return assumption | F10: 0.04 | G10: 0.06 | H10: 0.09
A11: Baseline retirement spend (non-housing) | B11: 200000 | E11: Retire after YOE cap (defaults from modeled years) | F11: =MAX(1,$B$19+2) -> 12 | G11: =$B$19 -> 10 | H11: =MAX(1,$B$19-1) -> 9
A12: No-growth return | B12: 0 | E12: Baseline retirement spend (non-housing) | F12: 170000 | G12: 200000 | H12: 240000
A13: Base return | B13: 0.06 | E13: Home purchase year | F13: 10 | G13: 10 | H13: 10 | J13: The base projection treats any nonblank gross-comp row on Savings Projection as a working year and any blank row as retired. Use Dashboard selected year for point-in-time readouts, and use the planning draw rate / housing share / liquidity floor to stress what house price and non-housing retirement spend look reasonable. Home leverage now uses a visible policy: the effective down payment scales up as the purchase gets closer to retirement, and you can still force a fixed down payment with a manual override.
A14: Upside return | B14: 0.08 | E14: Home purchase price | F14: 5000000 | G14: 5000000 | H14: 5000000
A15: Dashboard selected year | B15: 10 | E15: Minimum down payment % | F15: 0.2 | G15: 0.2 | H15: 0.2
A16: Planning draw rate target | B16: 0.035 | E16: Mortgage rate | F16: 0.065 | G16: 0.065 | H16: 0.065
A17: Target housing share of total spend | B17: 0.35 | E17: Mortgage term (years) | F17: 30 | G17: 30 | H17: 30
A18: Minimum liquid reserve after purchase | B18: 1000000 | E18: Closing costs % | F18: 0.025 | G18: 0.025 | H18: 0.025
A19: Derived working years | B19: ='Savings Projection'!$B$12 -> 10 | E19: Property tax rate | F19: 0.01 | G19: 0.01 | H19: 0.01
E20: Home insurance rate | F20: 0.002 | G20: 0.002 | H20: 0.002
A21: Compensation Assumptions | E21: Home maintenance rate | F21: 0.01 | G21: 0.01 | H21: 0.01
A22: Start calendar year | B22: 2026 | E22: Annual HOA / common charges | F22: 0 | G22: 0 | H22: 0
A23: Start month | B23: 9 | E23: Annual home services / utilities | F23: 0 | G23: 0 | H23: 0
A24: Default modeled working years | B24: 10 | E24: One-time move / furnish reserve | F24: 0 | G24: 0 | H24: 0 | J24: Compensation reflects actual Jump Trading offer terms. September 14, 2026 start: prorated base + $450K sign-on paid in 2026 - no guaranteed bonus cash in 2026. FY2026 pro-rated guaranteed bonus ($450K x 4/12 = $150K) is received in calendar 2027. FY2027 full guaranteed bonus ($450K) is received in calendar 2028. From 2029 onward bonuses are discretionary, modeled growing from $450K at the early ramp rate. Bonus Overrides (AX col) lock years 1-3; the Trend Bonus formula starts the growth clock from Year 3. Session 3 refined this to a tranche-aware 50/25/25 split so each FY bonus pays 75% in the next CY and 25% in the CY after, and added Savings Projection columns BJ (cash received) and BK (unvested YE). 2026-04-11 IC quant median calibration: early bonus growth is about 45.3% and later growth about 27.1%, which makes the pre-swing trend total comp approximately $1.25M in projection year 5 and $2.25M in projection year 8. Those targets reflect the discussed median IC ranges of $1.0M-$1.5M by Y5 and $1.5M-$3.0M by Y8; Savings Projection column B remains cash received and therefore lags the accrued trend under the deferral schedule.
A25: Standard annual base salary | B25: 300000 | E25: Home appreciation | F25: 0.03 | G25: 0.03 | H25: 0.03
A26: Stub-year sign-on bonus | B26: 450000 | E26: Down payment % if buying at / after retirement | F26: 0.5 | G26: 0.45 | H26: 0.4
A27: Guaranteed annual bonus (FY2026–27, paid following yr) | B27: 450000 | E27: Working years until minimum down payment | F27: 5 | G27: 5 | H27: 4
A28: Early bonus growth rate | B28: 0.45296631 | E28: Manual down payment override %
A29: Later bonus growth rate | B29: 0.27087744
A30: Switch to later growth after proj. year | B30: 4
A31: Annual base growth | B31: 0
A32: Bonus fluctuation amplitude | B32: 0.12
A33: Bonus fluctuation cycle (years) | B33: 3
A34: Bonus fluctuation phase shift | B34: 0
A35: Rent inflation (annual) | B35: 0.03
A36: Living cost inflation (annual) | B36: 0.03

Sheet Savings Projection
A1: Savings And Retirement Projection
A2: Blue cells in the yearly table are inputs. Gross comp now flows from the visible compensation schedule on the right, while this sheet keeps all tax math and year-by-year savings / retirement logic visible.
A4: Setup | F4: Interpretation | M4: Tax And Retirement Modeling Notes | AN4: Compensation Schedule (Feeds Gross Comp)
A5: Filing status | B5: ='Model Inputs'!$B$5 -> Single | F5: The 401(k) column auto-fills from the visible annual limit in the tax sheet and reduces federal, NY State, and NYC taxable income. | M5: Talent.com showed about $674,633 net on $1.2M in New York as of 2026-04-03. | AN5: Edit the comp logic here instead of typing raw gross comp into the main output column. Per the Jump Trading offer letter (Addendum PDF): base $300K, guaranteed annual bonus $450K for FY2026 and FY2027, $450K sign-on in 2026 only. Start date Sep 2026 so FY2026 guarantee is prorated by 4/12 = $150K (accrued). Bonuses are paid on a deferred 50/25/25 schedule: 50% by March 15 following FY end, 25% six months later, 25% twelve months later. This splits each FY bonus across TWO calendar years (75% / 25%). Columns: AY = FY accrued (this is the accrual-basis number, pinned via AX for FY2026 and FY2027), BJ = CY cash received (tranche sum), BB = total CY cash gross comp (uses BJ, not AY). BK = year-end unvested deferred comp ('golden handcuffs' walk-away cost). BD:BI = Realized Comp (Actuals) input block; fill BE with actual accrued FY bonuses as they are announced and they will flow through the same 75/25 tranche logic to BD (which overrides BB when non-blank).
A6: Resident city | B6: ='Model Inputs'!$B$6 -> New York City | F6: HSA contributions reduce federal taxable income and FICA wages, but New York generally adds them back for state and city income tax. | M6: This workbook stays lower because it models NYC resident tax separately and uses the 2026 SSA wage base.
A7: Starting taxable assets | B7: ='Model Inputs'!$B$7 -> 150000 | F7: Roth IRA is modeled as a post-tax transfer from working-year cash flow; at this income level, treat it as a backdoor Roth assumption. | M7: The front-page graphs now continue through retirement years instead of falling to zero after work stops.
A8: Starting 401(k) balance | B8: ='Model Inputs'!$B$8 -> 0 | F8: Any nonblank gross-comp row is treated as Working, and any blank gross-comp row is treated as Retired. | M8: Bucket balances are base-return only; total-wealth paths are shown for 0%, base, and upside return assumptions.
A9: Starting Roth balance | B9: ='Model Inputs'!$B$9 -> 0 | F9: Retirement withdrawals start automatically on retired rows and fund baseline non-housing spending from taxable, then 401(k), then Roth, then HSA. | M9: Starting wealth can be split across taxable, 401(k), Roth, and HSA buckets so the dashboard reflects your real account mix.
A10: Starting HSA balance | B10: ='Model Inputs'!$B$10 -> 0 | F10: House purchase and housing carry are modeled on Scenario Lab so retirement housing costs sit on top of this baseline spend instead of being buried inside it. | M10: The retirement section is designed for directional planning rather than full distribution-tax optimization.
A11: Total starting investable assets | B11: =SUM(B7:B10) -> 150000 | F11: The compensation schedule on the right models a September 2026 stub year with prorated base and guaranteed bonus, then a faster early bonus ramp, a slower later ramp, and a visible deterministic fluctuation layer. To extend beyond the default working years, fill Gross Comp Input or the other override cells on later rows. The main Gross Comp column is output-only and feeds from the modeled schedule plus the visible input column. | M11: Scenario and house assumptions are edited on Model Inputs and flow through Scenario Lab as linked calculations.
A12: Working years entered | B12: =IFERROR(LOOKUP(2,1/($C$19:$C$58="Working"),$A$19:$A$58),0) -> 10
A13: Baseline retirement spend (non-housing) | B13: ='Model Inputs'!$B$11 -> 200000
A14: No-growth return | B14: ='Model Inputs'!$B$12 -> 0
A15: Base return | B15: ='Model Inputs'!$B$13 -> 0.06
A16: Upside return | B16: ='Model Inputs'!$B$14 -> 0.08
A17: Dashboard selected year | B17: ='Model Inputs'!$B$15 -> 10
A18: Year | B18: Gross Comp (output) | C18: Phase | D18: 401(k) / Trad | E18: HSA | F18: After-Tax Payroll | G18: Fed Taxable Income | H18: Federal Tax | I18: Social Security | J18: Medicare | K18: Add'l Medicare | L18: NY PFL | M18: NY Disability | N18: NY Taxable Income | O18: NY State Tax | P18: NYC Tax | Q18: Total Tax / Deductions | R18: Post-Tax Cash | S18: Rent (nominal) | T18: Other Living Costs (nominal) | U18: Cash After Living | V18: Roth IRA / Backdoor Roth | W18: Taxable Savings / (Draw) | X18: Total Annual Savings | Y18: Planned Retirement Withdrawal | Z18: Actual Withdrawal | AA18: Taxable Withdrawal | AB18: 401(k) Withdrawal | AC18: Roth Withdrawal | AD18: HSA Withdrawal | AE18: Taxable Balance | AF18: 401(k) Balance | AG18: Roth Balance | AH18: HSA Balance | AI18: Total Wealth @ Base | AJ18: Total Wealth @ 0% | AK18: Total Wealth @ 8% | AL18: Taxable Savings Rate | AM18: Total Savings Rate | AN18: Proj. Year | AO18: Calendar Year | AP18: Work Fraction | AQ18: Default Base | AR18: Base Override | AS18: Base Used | AT18: Base Earned | AU18: Trend Bonus | AV18: Default Swing % | AW18: Swing Override % | AX18: FY Bonus Accrual Override | AY18: FY Bonus Accrued | AZ18: Sign-On / One-Time | BA18: Other Cash Comp | BB18: Modeled Gross Comp | BC18: Gross Comp Input | BD18: Actual CY Gross Comp | BE18: FY Bonus Earned (paid next CY) | BF18: CY Base Actual | BG18: CY Other / Sign-On Actual | BH18: Confirmed? | BI18: Notes | BJ18: Bonus Cash Received | BK18: Unvested Deferred Comp (YE) | BL18: Rent (real $) | BM18: Living (real $)
A19: 1 | B19: =IF(BB19="","",BB19) -> 550000 | C19: =IF(B19="","Retired","Working") -> Working | D19: =IF(OR(C19="Retired",B19=""),0,MIN(B19,'Tax Assumptions'!$B$19)) -> 24500 | E19: 0 | F19: 0 | G19: =IF(C19="Working",MAX(B19-D19-E19-'Tax Assumptions'!$B$8,0),0) -> 509400 | H19: =IF(G19=0,0,LOOKUP(G19,'Tax Assumptions'!$F$9:$F$15,'Tax Assumptions'!$I$9:$I$15)+(G19-LOOKUP(G19,'Tax Assumptions'!$F$9:$F$15,'Tax Assumptions'!$F$9:$F$15))*LOOKUP(G19,'Tax Assumptions'!$F$9:$F$15,'Tax Assumptions'!$H$9:$H$15)) -> 147059.25 | I19: =IF(C19="Working",MIN(MAX(B19-E19,0),'Tax Assumptions'!$B$11)*'Tax Assumptions'!$B$10,0) -> 11439 | J19: =IF(C19="Working",MAX(B19-E19,0)*'Tax Assumptions'!$B$12,0) -> 7975 | K19: =IF(C19="Working",MAX(MAX(B19-E19,0)-'Tax Assumptions'!$B$14,0)*'Tax Assumptions'!$B$13,0) -> 3150 | L19: =IF(C19="Working",MIN(B19*'Tax Assumptions'!$B$15,'Tax Assumptions'!$B$16),0) -> 411.91 | M19: =IF(C19="Working",MIN(B19*'Tax Assumptions'!$B$17,'Tax Assumptions'!$B$18),0) -> 31.2 | N19: =IF(C19="Working",MAX(B19-D19-'Tax Assumptions'!$B$9,0),0) -> 517500 | O19: =IF(N19=0,0,LOOKUP(N19,'Tax Assumptions'!$K$9:$K$17,'Tax Assumptions'!$N$9:$N$17)+(N19-LOOKUP(N19,'Tax Assumptions'!$K$9:$K$17,'Tax Assumptions'!$K$9:$K$17))*LOOKUP(N19,'Tax Assumptions'!$K$9:$K$17,'Tax Assumptions'!$M$9:$M$17)) -> 32834.7 | P19: =IF(N19=0,0,LOOKUP(N19,'Tax Assumptions'!$P$9:$P$12,'Tax Assumptions'!$S$9:$S$12)+(N19-LOOKUP(N19,'Tax Assumptions'!$P$9:$P$12,'Tax Assumptions'!$P$9:$P$12))*LOOKUP(N19,'Tax Assumptions'!$P$9:$P$12,'Tax Assumptions'!$R$9:$R$12)) -> 19933.47 | Q19: =H19+I19+J19+K19+L19+M19+O19+P19 -> 222834.53 | R19: =IF(C19="Working",B19-D19-E19-F19-Q19,0) -> 302665.47 | S19: =IF(C19="Working",IF(BL19="","",BL19*(1+'Model Inputs'!$B$35)^(AN19-1)),"") -> 78000 | T19: =IF(C19="Working",IF(BM19="","",BM19*(1+'Model Inputs'!$B$36)^(AN19-1)),"") -> 40000 | U19: =IF(C19="Working",R19-S19-T19,0) -> 184665.47 | V19: =IF(C19="Working",MIN(MAX(U19,0),'Tax Assumptions'!$B$20),0) -> 7500 | W19: =IF(C19="Working",U19-V19,0) -> 177165.47 | X19: =IF(C19="Working",W19+V19+D19+E19,0) -> 209165.47 | Y19: =IF(C19="Retired",$B$13,0) -> 0 | Z19: =AA19+AB19+AC19+AD19 -> 0 | AA19: =IF(C19="Retired",MIN(Y19,(($B$7)*(1+$B$15)+IF(C19="Working",W19,0))),0) -> 0 | AB19: =IF(C19="Retired",MIN(MAX(Y19-AA19,0),(($B$8)*(1+$B$15)+IF(C19="Working",D19,0))),0) -> 0 | AC19: =IF(C19="Retired",MIN(MAX(Y19-AA19-AB19,0),(($B$9)*(1+$B$15)+IF(C19="Working",V19,0))),0) -> 0 | AD19: =IF(C19="Retired",MIN(MAX(Y19-AA19-AB19-AC19,0),(($B$10)*(1+$B$15)+IF(C19="Working",E19,0))),0) -> 0 | AE19: =MAX((($B$7)*(1+$B$15)+IF(C19="Working",W19,0))-AA19,0) -> 336165.47 | AF19: =MAX((($B$8)*(1+$B$15)+IF(C19="Working",D19,0))-AB19,0) -> 24500 | AG19: =MAX((($B$9)*(1+$B$15)+IF(C19="Working",V19,0))-AC19,0) -> 7500 | AH19: =MAX((($B$10)*(1+$B$15)+IF(C19="Working",E19,0))-AD19,0) -> 0 | AI19: =AE19+AF19+AG19+AH19 -> 368165.47 | AJ19: =IF(C19="Working",SUM($B$7:$B$10)+X19,MAX(SUM($B$7:$B$10)-MIN(Y19,SUM($B$7:$B$10)),0)) -> 359165.47 | AK19: =IF(C19="Working",SUM($B$7:$B$10)*(1+$B$16)+X19,MAX(SUM($B$7:$B$10)*(1+$B$16)-MIN(Y19,SUM($B$7:$B$10)*(1+$B$16)),0)) -> 371165.47 | AL19: =IF(C19="Working",IF(B19=0,0,W19/B19),0) -> 0.32211904 | AM19: =IF(C19="Working",IF(B19=0,0,X19/B19),0) -> 0.38030085 | AN19: =A19 -> 1 | AO19: ='Model Inputs'!$B$22+AN19-1 -> 2026 | AP19: =IF(AND(AQ19="",AR19="",AX19="",BA19="",BC19=""),"",IF(AN19=1,(13-'Model Inputs'!$B$23)/12,1)) -> 0.33333333 | AQ19: =IF(OR(AN19<='Model Inputs'!$B$24,AR19<>"",AX19<>"",BA19<>"",BC19<>""),'Model Inputs'!$B$25*(1+'Model Inputs'!$B$31)^(AN19-1),"") -> 300000 | AS19: =IF(AP19="","",IF(AR19="",AQ19,AR19)) -> 300000 | AT19: =IF(AS19="","",AP19*AS19) -> 100000 | AU19: =IF(AP19="","",IF(AN19=1,(13-'Model Inputs'!$B$23)/12*'Model Inputs'!$B$27,IF(AN19=2,'Model Inputs'!$B$27,IF(AN19<=MAX(3,'Model Inputs'!$B$30+1),'Model Inputs'!$B$27*(1+'Model Inputs'!$B$28)^(AN19-3),'Model Inputs'!$B$27*(1+'Model Inputs'!$B$28)^(MAX(3,'Model Inputs'!$B$30+1)-3)*(1+'Model Inputs'!$B$29)^(AN19-MAX(3,'Model Inputs'!$B$30+1)))))) -> 150000 | AV19: =IF(AU19="","",IF(AN19<=2,0,'Model Inputs'!$B$32*SIN(2*PI()*(AN19-3+'Model Inputs'!$B$34)/MAX(1,'Model Inputs'!$B$33)))) -> 0 | AX19: 150000 | AY19: =IF(AP19="","",IF(AX19<>"",AX19,AU19*(1+IF(AW19="",AV19,AW19)))) -> 150000 | AZ19: =IF(AN19=1,'Model Inputs'!$B$26,"") -> 450000 | BA19: 0 | BB19: =IF(AND(AS19="",BJ19="",AZ19="",BA19="",BC19="",BD19=""),"",IF(BD19<>"",BD19,IF(BC19<>"",BC19,AT19+IF(BJ19="",0,BJ19)+IF(AZ19="",0,AZ19)+IF(BA19="",0,BA19)))) -> 550000 | BD19: =IF(AND(BF19="",BG19=""),"",IF(BF19<>"",BF19,IF(AT19="",0,AT19))+IF(BG19<>"",BG19,IF(AZ19="",0,AZ19)+IF(BA19="",0,BA19))) | BJ19: =IF(AP19="","",0) -> 0 | BK19: =IF(AP19="","",IF(AY19="",0,AY19)) -> 150000 | BL19: 78000 | BM19: 40000
A20: 2 | B20: =IF(BB20="","",BB20) -> 412500 | C20: =IF(B20="","Retired","Working") -> Working | D20: =IF(OR(C20="Retired",B20=""),0,MIN(B20,'Tax Assumptions'!$B$19)) -> 24500 | E20: 0 | F20: 0 | G20: =IF(C20="Working",MAX(B20-D20-E20-'Tax Assumptions'!$B$8,0),0) -> 371900 | H20: =IF(G20=0,0,LOOKUP(G20,'Tax Assumptions'!$F$9:$F$15,'Tax Assumptions'!$I$9:$I$15)+(G20-LOOKUP(G20,'Tax Assumptions'!$F$9:$F$15,'Tax Assumptions'!$F$9:$F$15))*LOOKUP(G20,'Tax Assumptions'!$F$9:$F$15,'Tax Assumptions'!$H$9:$H$15)) -> 98934.25 | I20: =IF(C20="Working",MIN(MAX(B20-E20,0),'Tax Assumptions'!$B$11)*'Tax Assumptions'!$B$10,0) -> 11439 | J20: =IF(C20="Working",MAX(B20-E20,0)*'Tax Assumptions'!$B$12,0) -> 5981.25 | K20: =IF(C20="Working",MAX(MAX(B20-E20,0)-'Tax Assumptions'!$B$14,0)*'Tax Assumptions'!$B$13,0) -> 1912.5 | L20: =IF(C20="Working",MIN(B20*'Tax Assumptions'!$B$15,'Tax Assumptions'!$B$16),0) -> 411.91 | M20: =IF(C20="Working",MIN(B20*'Tax Assumptions'!$B$17,'Tax Assumptions'!$B$18),0) -> 31.2 | N20: =IF(C20="Working",MAX(B20-D20-'Tax Assumptions'!$B$9,0),0) -> 380000 | O20: =IF(N20=0,0,LOOKUP(N20,'Tax Assumptions'!$K$9:$K$17,'Tax Assumptions'!$N$9:$N$17)+(N20-LOOKUP(N20,'Tax Assumptions'!$K$9:$K$17,'Tax Assumptions'!$K$9:$K$17))*LOOKUP(N20,'Tax Assumptions'!$K$9:$K$17,'Tax Assumptions'!$M$9:$M$17)) -> 23415.95 | P20: =IF(N20=0,0,LOOKUP(N20,'Tax Assumptions'!$P$9:$P$12,'Tax Assumptions'!$S$9:$S$12)+(N20-LOOKUP(N20,'Tax Assumptions'!$P$9:$P$12,'Tax Assumptions'!$P$9:$P$12))*LOOKUP(N20,'Tax Assumptions'!$P$9:$P$12,'Tax Assumptions'!$R$9:$R$12)) -> 14603.97 | Q20: =H20+I20+J20+K20+L20+M20+O20+P20 -> 156730.03 | R20: =IF(C20="Working",B20-D20-E20-F20-Q20,0) -> 231269.97 | S20: =IF(C20="Working",IF(BL20="","",BL20*(1+'Model Inputs'!$B$35)^(AN20-1)),"") -> 80340 | T20: =IF(C20="Working",IF(BM20="","",BM20*(1+'Model Inputs'!$B$36)^(AN20-1)),"") -> 41200 | U20: =IF(C20="Working",R20-S20-T20,0) -> 109729.97 | V20: =IF(C20="Working",MIN(MAX(U20,0),'Tax Assumptions'!$B$20),0) -> 7500 | W20: =IF(C20="Working",U20-V20,0) -> 102229.97 | X20: =IF(C20="Working",W20+V20+D20+E20,0) -> 134229.97 | Y20: =IF(C20="Retired",$B$13,0) -> 0 | Z20: =AA20+AB20+AC20+AD20 -> 0 | AA20: =IF(C20="Retired",MIN(Y20,((AE19)*(1+$B$15)+IF(C20="Working",W20,0))),0) -> 0 | AB20: =IF(C20="Retired",MIN(MAX(Y20-AA20,0),((AF19)*(1+$B$15)+IF(C20="Working",D20,0))),0) -> 0 | AC20: =IF(C20="Retired",MIN(MAX(Y20-AA20-AB20,0),((AG19)*(1+$B$15)+IF(C20="Working",V20,0))),0) -> 0 | AD20: =IF(C20="Retired",MIN(MAX(Y20-AA20-AB20-AC20,0),((AH19)*(1+$B$15)+IF(C20="Working",E20,0))),0) -> 0 | AE20: =MAX(((AE19)*(1+$B$15)+IF(C20="Working",W20,0))-AA20,0) -> 458565.37 | AF20: =MAX(((AF19)*(1+$B$15)+IF(C20="Working",D20,0))-AB20,0) -> 50470 | AG20: =MAX(((AG19)*(1+$B$15)+IF(C20="Working",V20,0))-AC20,0) -> 15450 | AH20: =MAX(((AH19)*(1+$B$15)+IF(C20="Working",E20,0))-AD20,0) -> 0 | AI20: =AE20+AF20+AG20+AH20 -> 524485.37 | AJ20: =IF(C20="Working",AJ19+X20,MAX(AJ19-MIN(Y20,AJ19),0)) -> 493395.44 | AK20: =IF(C20="Working",AK19*(1+$B$16)+X20,MAX(AK19*(1+$B$16)-MIN(Y20,AK19*(1+$B$16)),0)) -> 535088.68 | AL20: =IF(C20="Working",IF(B20=0,0,W20/B20),0) -> 0.24783023 | AM20: =IF(C20="Working",IF(B20=0,0,X20/B20),0) -> 0.32540599 | AN20: =A20 -> 2 | AO20: ='Model Inputs'!$B$22+AN20-1 -> 2027 | AP20: =IF(AND(AQ20="",AR20="",AX20="",BA20="",BC20=""),"",IF(AN20=1,(13-'Model Inputs'!$B$23)/12,1)) -> 1 | AQ20: =IF(OR(AN20<='Model Inputs'!$B$24,AR20<>"",AX20<>"",BA20<>"",BC20<>""),'Model Inputs'!$B$25*(1+'Model Inputs'!$B$31)^(AN20-1),"") -> 300000 | AS20: =IF(AP20="","",IF(AR20="",AQ20,AR20)) -> 300000 | AT20: =IF(AS20="","",AP20*AS20) -> 300000 | AU20: =IF(AP20="","",IF(AN20=1,(13-'Model Inputs'!$B$23)/12*'Model Inputs'!$B$27,IF(AN20=2,'Model Inputs'!$B$27,IF(AN20<=MAX(3,'Model Inputs'!$B$30+1),'Model Inputs'!$B$27*(1+'Model Inputs'!$B$28)^(AN20-3),'Model Inputs'!$B$27*(1+'Model Inputs'!$B$28)^(MAX(3,'Model Inputs'!$B$30+1)-3)*(1+'Model Inputs'!$B$29)^(AN20-MAX(3,'Model Inputs'!$B$30+1)))))) -> 450000 | AV20: =IF(AU20="","",IF(AN20<=2,0,'Model Inputs'!$B$32*SIN(2*PI()*(AN20-3+'Model Inputs'!$B$34)/MAX(1,'Model Inputs'!$B$33)))) -> 0 | AX20: 450000 | AY20: =IF(AP20="","",IF(AX20<>"",AX20,AU20*(1+IF(AW20="",AV20,AW20)))) -> 450000 | AZ20: =IF(AN20=1,'Model Inputs'!$B$26,"") | BA20: 0 | BB20: =IF(AND(AS20="",BJ20="",AZ20="",BA20="",BC20="",BD20=""),"",IF(BD20<>"",BD20,IF(BC20<>"",BC20,AT20+IF(BJ20="",0,BJ20)+IF(AZ20="",0,AZ20)+IF(BA20="",0,BA20)))) -> 412500 | BD20: =IF(AND(BF20="",BG20="",BE19=""),"",IF(BF20<>"",BF20,IF(AT20="",0,AT20))+0.75*IF(BE19<>"",BE19,IF(AY19="",0,AY19))+IF(BG20<>"",BG20,IF(AZ20="",0,AZ20)+IF(BA20="",0,BA20))) | BJ20: =IF(AP20="","",0.75*IF(AY19="",0,AY19)) -> 112500 | BK20: =IF(AP20="","",IF(AY20="",0,AY20)+0.25*IF(AY19="",0,AY19)) -> 487500 | BL20: 78000 | BM20: 40000
A21: 3 | B21: =IF(BB21="","",BB21) -> 675000 | C21: =IF(B21="","Retired","Working") -> Working | D21: =IF(OR(C21="Retired",B21=""),0,MIN(B21,'Tax Assumptions'!$B$19)) -> 24500 | E21: 0 | F21: 0 | G21: =IF(C21="Working",MAX(B21-D21-E21-'Tax Assumptions'!$B$8,0),0) -> 634400 | H21: =IF(G21=0,0,LOOKUP(G21,'Tax Assumptions'!$F$9:$F$15,'Tax Assumptions'!$I$9:$I$15)+(G21-LOOKUP(G21,'Tax Assumptions'!$F$9:$F$15,'Tax Assumptions'!$F$9:$F$15))*LOOKUP(G21,'Tax Assumptions'!$F$9:$F$15,'Tax Assumptions'!$H$9:$H$15)) -> 190809.25 | I21: =IF(C21="Working",MIN(MAX(B21-E21,0),'Tax Assumptions'!$B$11)*'Tax Assumptions'!$B$10,0) -> 11439 | J21: =IF(C21="Working",MAX(B21-E21,0)*'Tax Assumptions'!$B$12,0) -> 9787.5 | K21: =IF(C21="Working",MAX(MAX(B21-E21,0)-'Tax Assumptions'!$B$14,0)*'Tax Assumptions'!$B$13,0) -> 4275 | L21: =IF(C21="Working",MIN(B21*'Tax Assumptions'!$B$15,'Tax Assumptions'!$B$16),0) -> 411.91 | M21: =IF(C21="Working",MIN(B21*'Tax Assumptions'!$B$17,'Tax Assumptions'!$B$18),0) -> 31.2 | N21: =IF(C21="Working",MAX(B21-D21-'Tax Assumptions'!$B$9,0),0) -> 642500 | O21: =IF(N21=0,0,LOOKUP(N21,'Tax Assumptions'!$K$9:$K$17,'Tax Assumptions'!$N$9:$N$17)+(N21-LOOKUP(N21,'Tax Assumptions'!$K$9:$K$17,'Tax Assumptions'!$K$9:$K$17))*LOOKUP(N21,'Tax Assumptions'!$K$9:$K$17,'Tax Assumptions'!$M$9:$M$17)) -> 41397.2 | P21: =IF(N21=0,0,LOOKUP(N21,'Tax Assumptions'!$P$9:$P$12,'Tax Assumptions'!$S$9:$S$12)+(N21-LOOKUP(N21,'Tax Assumptions'!$P$9:$P$12,'Tax Assumptions'!$P$9:$P$12))*LOOKUP(N21,'Tax Assumptions'!$P$9:$P$12,'Tax Assumptions'!$R$9:$R$12)) -> 24778.47 | Q21: =H21+I21+J21+K21+L21+M21+O21+P21 -> 282929.53 | R21: =IF(C21="Working",B21-D21-E21-F21-Q21,0) -> 367570.47 | S21: =IF(C21="Working",IF(BL21="","",BL21*(1+'Model Inputs'!$B$35)^(AN21-1)),"") -> 82750.2 | T21: =IF(C21="Working",IF(BM21="","",BM21*(1+'Model Inputs'!$B$36)^(AN21-1)),"") -> 53045 | U21: =IF(C21="Working",R21-S21-T21,0) -> 231775.27 | V21: =IF(C21="Working",MIN(MAX(U21,0),'Tax Assumptions'!$B$20),0) -> 7500 | W21: =IF(C21="Working",U21-V21,0) -> 224275.27 | X21: =IF(C21="Working",W21+V21+D21+E21,0) -> 256275.27 | Y21: =IF(C21="Retired",$B$13,0) -> 0 | Z21: =AA21+AB21+AC21+AD21 -> 0 | AA21: =IF(C21="Retired",MIN(Y21,((AE20)*(1+$B$15)+IF(C21="Working",W21,0))),0) -> 0 | AB21: =IF(C21="Retired",MIN(MAX(Y21-AA21,0),((AF20)*(1+$B$15)+IF(C21="Working",D21,0))),0) -> 0 | AC21: =IF(C21="Retired",MIN(MAX(Y21-AA21-AB21,0),((AG20)*(1+$B$15)+IF(C21="Working",V21,0))),0) -> 0 | AD21: =IF(C21="Retired",MIN(MAX(Y21-AA21-AB21-AC21,0),((AH20)*(1+$B$15)+IF(C21="Working",E21,0))),0) -> 0 | AE21: =MAX(((AE20)*(1+$B$15)+IF(C21="Working",W21,0))-AA21,0) -> 710354.56 | AF21: =MAX(((AF20)*(1+$B$15)+IF(C21="Working",D21,0))-AB21,0) -> 77998.2 | AG21: =MAX(((AG20)*(1+$B$15)+IF(C21="Working",V21,0))-AC21,0) -> 23877 | AH21: =MAX(((AH20)*(1+$B$15)+IF(C21="Working",E21,0))-AD21,0) -> 0 | AI21: =AE21+AF21+AG21+AH21 -> 812229.76 | AJ21: =IF(C21="Working",AJ20+X21,MAX(AJ20-MIN(Y21,AJ20),0)) -> 749670.71 | AK21: =IF(C21="Working",AK20*(1+$B$16)+X21,MAX(AK20*(1+$B$16)-MIN(Y21,AK20*(1+$B$16)),0)) -> 834171.04 | AL21: =IF(C21="Working",IF(B21=0,0,W21/B21),0) -> 0.33225966 | AM21: =IF(C21="Working",IF(B21=0,0,X21/B21),0) -> 0.37966707 | AN21: =A21 -> 3 | AO21: ='Model Inputs'!$B$22+AN21-1 -> 2028 | AP21: =IF(AND(AQ21="",AR21="",AX21="",BA21="",BC21=""),"",IF(AN21=1,(13-'Model Inputs'!$B$23)/12,1)) -> 1 | AQ21: =IF(OR(AN21<='Model Inputs'!$B$24,AR21<>"",AX21<>"",BA21<>"",BC21<>""),'Model Inputs'!$B$25*(1+'Model Inputs'!$B$31)^(AN21-1),"") -> 300000 | AS21: =IF(AP21="","",IF(AR21="",AQ21,AR21)) -> 300000 | AT21: =IF(AS21="","",AP21*AS21) -> 300000 | AU21: =IF(AP21="","",IF(AN21=1,(13-'Model Inputs'!$B$23)/12*'Model Inputs'!$B$27,IF(AN21=2,'Model Inputs'!$B$27,IF(AN21<=MAX(3,'Model Inputs'!$B$30+1),'Model Inputs'!$B$27*(1+'Model Inputs'!$B$28)^(AN21-3),'Model Inputs'!$B$27*(1+'Model Inputs'!$B$28)^(MAX(3,'Model Inputs'!$B$30+1)-3)*(1+'Model Inputs'!$B$29)^(AN21-MAX(3,'Model Inputs'!$B$30+1)))))) -> 450000 | AV21: =IF(AU21="","",IF(AN21<=2,0,'Model Inputs'!$B$32*SIN(2*PI()*(AN21-3+'Model Inputs'!$B$34)/MAX(1,'Model Inputs'!$B$33)))) -> 0 | AY21: =IF(AP21="","",IF(AX21<>"",AX21,AU21*(1+IF(AW21="",AV21,AW21)))) -> 450000 | AZ21: =IF(AN21=1,'Model Inputs'!$B$26,"") | BA21: 0 | BB21: =IF(AND(AS21="",BJ21="",AZ21="",BA21="",BC21="",BD21=""),"",IF(BD21<>"",BD21,IF(BC21<>"",BC21,AT21+IF(BJ21="",0,BJ21)+IF(AZ21="",0,AZ21)+IF(BA21="",0,BA21)))) -> 675000 | BD21: =IF(AND(BF21="",BG21="",BE20="",BE19=""),"",IF(BF21<>"",BF21,IF(AT21="",0,AT21))+0.75*IF(BE20<>"",BE20,IF(AY20="",0,AY20))+0.25*IF(BE19<>"",BE19,IF(AY19="",0,AY19))+IF(BG21<>"",BG21,IF(AZ21="",0,AZ21)+IF(BA21="",0,BA21))) | BJ21: =IF(AP21="","",0.75*IF(AY20="",0,AY20)+0.25*IF(AY19="",0,AY19)) -> 375000 | BK21: =IF(AP21="","",IF(AY21="",0,AY21)+0.25*IF(AY20="",0,AY20)) -> 562500 | BL21: 78000 | BM21: 50000
A22: 4 | B22: =IF(BB22="","",BB22) -> 750000 | C22: =IF(B22="","Retired","Working") -> Working | D22: =IF(OR(C22="Retired",B22=""),0,MIN(B22,'Tax Assumptions'!$B$19)) -> 24500 | E22: 0 | F22: 0 | G22: =IF(C22="Working",MAX(B22-D22-E22-'Tax Assumptions'!$B$8,0),0) -> 709400 | H22: =IF(G22=0,0,LOOKUP(G22,'Tax Assumptions'!$F$9:$F$15,'Tax Assumptions'!$I$9:$I$15)+(G22-LOOKUP(G22,'Tax Assumptions'!$F$9:$F$15,'Tax Assumptions'!$F$9:$F$15))*LOOKUP(G22,'Tax Assumptions'!$F$9:$F$15,'Tax Assumptions'!$H$9:$H$15)) -> 218435.25 | I22: =IF(C22="Working",MIN(MAX(B22-E22,0),'Tax Assumptions'!$B$11)*'Tax Assumptions'!$B$10,0) -> 11439 | J22: =IF(C22="Working",MAX(B22-E22,0)*'Tax Assumptions'!$B$12,0) -> 10875 | K22: =IF(C22="Working",MAX(MAX(B22-E22,0)-'Tax Assumptions'!$B$14,0)*'Tax Assumptions'!$B$13,0) -> 4950 | L22: =IF(C22="Working",MIN(B22*'Tax Assumptions'!$B$15,'Tax Assumptions'!$B$16),0) -> 411.91 | M22: =IF(C22="Working",MIN(B22*'Tax Assumptions'!$B$17,'Tax Assumptions'!$B$18),0) -> 31.2 | N22: =IF(C22="Working",MAX(B22-D22-'Tax Assumptions'!$B$9,0),0) -> 717500 | O22: =IF(N22=0,0,LOOKUP(N22,'Tax Assumptions'!$K$9:$K$17,'Tax Assumptions'!$N$9:$N$17)+(N22-LOOKUP(N22,'Tax Assumptions'!$K$9:$K$17,'Tax Assumptions'!$K$9:$K$17))*LOOKUP(N22,'Tax Assumptions'!$K$9:$K$17,'Tax Assumptions'!$M$9:$M$17)) -> 46534.7 | P22: =IF(N22=0,0,LOOKUP(N22,'Tax Assumptions'!$P$9:$P$12,'Tax Assumptions'!$S$9:$S$12)+(N22-LOOKUP(N22,'Tax Assumptions'!$P$9:$P$12,'Tax Assumptions'!$P$9:$P$12))*LOOKUP(N22,'Tax Assumptions'!$P$9:$P$12,'Tax Assumptions'!$R$9:$R$12)) -> 27685.47 | Q22: =H22+I22+J22+K22+L22+M22+O22+P22 -> 320362.53 | R22: =IF(C22="Working",B22-D22-E22-F22-Q22,0) -> 405137.47 | S22: =IF(C22="Working",IF(BL22="","",BL22*(1+'Model Inputs'!$B$35)^(AN22-1)),"") -> 85232.706 | T22: =IF(C22="Working",IF(BM22="","",BM22*(1+'Model Inputs'!$B$36)^(AN22-1)),"") -> 54636.35 | U22: =IF(C22="Working",R22-S22-T22,0) -> 265268.41 | V22: =IF(C22="Working",MIN(MAX(U22,0),'Tax Assumptions'!$B$20),0) -> 7500 | W22: =IF(C22="Working",U22-V22,0) -> 257768.41 | X22: =IF(C22="Working",W22+V22+D22+E22,0) -> 289768.41 | Y22: =IF(C22="Retired",$B$13,0) -> 0 | Z22: =AA22+AB22+AC22+AD22 -> 0 | AA22: =IF(C22="Retired",MIN(Y22,((AE21)*(1+$B$15)+IF(C22="Working",W22,0))),0) -> 0 | AB22: =IF(C22="Retired",MIN(MAX(Y22-AA22,0),((AF21)*(1+$B$15)+IF(C22="Working",D22,0))),0) -> 0 | AC22: =IF(C22="Retired",MIN(MAX(Y22-AA22-AB22,0),((AG21)*(1+$B$15)+IF(C22="Working",V22,0))),0) -> 0 | AD22: =IF(C22="Retired",MIN(MAX(Y22-AA22-AB22-AC22,0),((AH21)*(1+$B$15)+IF(C22="Working",E22,0))),0) -> 0 | AE22: =MAX(((AE21)*(1+$B$15)+IF(C22="Working",W22,0))-AA22,0) -> 1010744.2 | AF22: =MAX(((AF21)*(1+$B$15)+IF(C22="Working",D22,0))-AB22,0) -> 107178.09 | AG22: =MAX(((AG21)*(1+$B$15)+IF(C22="Working",V22,0))-AC22,0) -> 32809.62 | AH22: =MAX(((AH21)*(1+$B$15)+IF(C22="Working",E22,0))-AD22,0) -> 0 | AI22: =AE22+AF22+AG22+AH22 -> 1150732 | AJ22: =IF(C22="Working",AJ21+X22,MAX(AJ21-MIN(Y22,AJ21),0)) -> 1039439.1 | AK22: =IF(C22="Working",AK21*(1+$B$16)+X22,MAX(AK21*(1+$B$16)-MIN(Y22,AK21*(1+$B$16)),0)) -> 1190673.1 | AL22: =IF(C22="Working",IF(B22=0,0,W22/B22),0) -> 0.34369122 | AM22: =IF(C22="Working",IF(B22=0,0,X22/B22),0) -> 0.38635789 | AN22: =A22 -> 4 | AO22: ='Model Inputs'!$B$22+AN22-1 -> 2029 | AP22: =IF(AND(AQ22="",AR22="",AX22="",BA22="",BC22=""),"",IF(AN22=1,(13-'Model Inputs'!$B$23)/12,1)) -> 1 | AQ22: =IF(OR(AN22<='Model Inputs'!$B$24,AR22<>"",AX22<>"",BA22<>"",BC22<>""),'Model Inputs'!$B$25*(1+'Model Inputs'!$B$31)^(AN22-1),"") -> 300000 | AS22: =IF(AP22="","",IF(AR22="",AQ22,AR22)) -> 300000 | AT22: =IF(AS22="","",AP22*AS22) -> 300000 | AU22: =IF(AP22="","",IF(AN22=1,(13-'Model Inputs'!$B$23)/12*'Model Inputs'!$B$27,IF(AN22=2,'Model Inputs'!$B$27,IF(AN22<=MAX(3,'Model Inputs'!$B$30+1),'Model Inputs'!$B$27*(1+'Model Inputs'!$B$28)^(AN22-3),'Model Inputs'!$B$27*(1+'Model Inputs'!$B$28)^(MAX(3,'Model Inputs'!$B$30+1)-3)*(1+'Model Inputs'!$B$29)^(AN22-MAX(3,'Model Inputs'!$B$30+1)))))) -> 653834.84 | AV22: =IF(AU22="","",IF(AN22<=2,0,'Model Inputs'!$B$32*SIN(2*PI()*(AN22-3+'Model Inputs'!$B$34)/MAX(1,'Model Inputs'!$B$33)))) -> 0.10392305 | AY22: =IF(AP22="","",IF(AX22<>"",AX22,AU22*(1+IF(AW22="",AV22,AW22)))) -> 721783.35 | AZ22: =IF(AN22=1,'Model Inputs'!$B$26,"") | BA22: 0 | BB22: =IF(AND(AS22="",BJ22="",AZ22="",BA22="",BC22="",BD22=""),"",IF(BD22<>"",BD22,IF(BC22<>"",BC22,AT22+IF(BJ22="",0,BJ22)+IF(AZ22="",0,AZ22)+IF(BA22="",0,BA22)))) -> 750000 | BD22: =IF(AND(BF22="",BG22="",BE21="",BE20=""),"",IF(BF22<>"",BF22,IF(AT22="",0,AT22))+0.75*IF(BE21<>"",BE21,IF(AY21="",0,AY21))+0.25*IF(BE20<>"",BE20,IF(AY20="",0,AY20))+IF(BG22<>"",BG22,IF(AZ22="",0,AZ22)+IF(BA22="",0,BA22))) | BJ22: =IF(AP22="","",0.75*IF(AY21="",0,AY21)+0.25*IF(AY20="",0,AY20)) -> 450000 | BK22: =IF(AP22="","",IF(AY22="",0,AY22)+0.25*IF(AY21="",0,AY21)) -> 834283.35 | BL22: 78000 | BM22: 50000
A23: 5 | B23: =IF(BB23="","",BB23) -> 953837.51 | C23: =IF(B23="","Retired","Working") -> Working | D23: =IF(OR(C23="Retired",B23=""),0,MIN(B23,'Tax Assumptions'!$B$19)) -> 24500 | E23: 0 | F23: 0 | G23: =IF(C23="Working",MAX(B23-D23-E23-'Tax Assumptions'!$B$8,0),0) -> 913237.51 | H23: =IF(G23=0,0,LOOKUP(G23,'Tax Assumptions'!$F$9:$F$15,'Tax Assumptions'!$I$9:$I$15)+(G23-LOOKUP(G23,'Tax Assumptions'!$F$9:$F$15,'Tax Assumptions'!$F$9:$F$15))*LOOKUP(G23,'Tax Assumptions'!$F$9:$F$15,'Tax Assumptions'!$H$9:$H$15)) -> 293855.13 | I23: =IF(C23="Working",MIN(MAX(B23-E23,0),'Tax Assumptions'!$B$11)*'Tax Assumptions'!$B$10,0) -> 11439 | J23: =IF(C23="Working",MAX(B23-E23,0)*'Tax Assumptions'!$B$12,0) -> 13830.644 | K23: =IF(C23="Working",MAX(MAX(B23-E23,0)-'Tax Assumptions'!$B$14,0)*'Tax Assumptions'!$B$13,0) -> 6784.5376 | L23: =IF(C23="Working",MIN(B23*'Tax Assumptions'!$B$15,'Tax Assumptions'!$B$16),0) -> 411.91 | M23: =IF(C23="Working",MIN(B23*'Tax Assumptions'!$B$17,'Tax Assumptions'!$B$18),0) -> 31.2 | N23: =IF(C23="Working",MAX(B23-D23-'Tax Assumptions'!$B$9,0),0) -> 921337.51 | O23: =IF(N23=0,0,LOOKUP(N23,'Tax Assumptions'!$K$9:$K$17,'Tax Assumptions'!$N$9:$N$17)+(N23-LOOKUP(N23,'Tax Assumptions'!$K$9:$K$17,'Tax Assumptions'!$K$9:$K$17))*LOOKUP(N23,'Tax Assumptions'!$K$9:$K$17,'Tax Assumptions'!$M$9:$M$17)) -> 60497.57 | P23: =IF(N23=0,0,LOOKUP(N23,'Tax Assumptions'!$P$9:$P$12,'Tax Assumptions'!$S$9:$S$12)+(N23-LOOKUP(N23,'Tax Assumptions'!$P$9:$P$12,'Tax Assumptions'!$P$9:$P$12))*LOOKUP(N23,'Tax Assumptions'!$P$9:$P$12,'Tax Assumptions'!$R$9:$R$12)) -> 35586.212 | Q23: =H23+I23+J23+K23+L23+M23+O23+P23 -> 422436.2 | R23: =IF(C23="Working",B23-D23-E23-F23-Q23,0) -> 506901.31 | S23: =IF(C23="Working",IF(BL23="","",BL23*(1+'Model Inputs'!$B$35)^(AN23-1)),"") -> 87789.687 | T23: =IF(C23="Working",IF(BM23="","",BM23*(1+'Model Inputs'!$B$36)^(AN23-1)),"") -> 56275.44 | U23: =IF(C23="Working",R23-S23-T23,0) -> 362836.18 | V23: =IF(C23="Working",MIN(MAX(U23,0),'Tax Assumptions'!$B$20),0) -> 7500 | W23: =IF(C23="Working",U23-V23,0) -> 355336.18 | X23: =IF(C23="Working",W23+V23+D23+E23,0) -> 387336.18 | Y23: =IF(C23="Retired",$B$13,0) -> 0 | Z23: =AA23+AB23+AC23+AD23 -> 0 | AA23: =IF(C23="Retired",MIN(Y23,((AE22)*(1+$B$15)+IF(C23="Working",W23,0))),0) -> 0 | AB23: =IF(C23="Retired",MIN(MAX(Y23-AA23,0),((AF22)*(1+$B$15)+IF(C23="Working",D23,0))),0) -> 0 | AC23: =IF(C23="Retired",MIN(MAX(Y23-AA23-AB23,0),((AG22)*(1+$B$15)+IF(C23="Working",V23,0))),0) -> 0 | AD23: =IF(C23="Retired",MIN(MAX(Y23-AA23-AB23-AC23,0),((AH22)*(1+$B$15)+IF(C23="Working",E23,0))),0) -> 0 | AE23: =MAX(((AE22)*(1+$B$15)+IF(C23="Working",W23,0))-AA23,0) -> 1426725.1 | AF23: =MAX(((AF22)*(1+$B$15)+IF(C23="Working",D23,0))-AB23,0) -> 138108.78 | AG23: =MAX(((AG22)*(1+$B$15)+IF(C23="Working",V23,0))-AC23,0) -> 42278.197 | AH23: =MAX(((AH22)*(1+$B$15)+IF(C23="Working",E23,0))-AD23,0) -> 0 | AI23: =AE23+AF23+AG23+AH23 -> 1607112.1 | AJ23: =IF(C23="Working",AJ22+X23,MAX(AJ22-MIN(Y23,AJ22),0)) -> 1426775.3 | AK23: =IF(C23="Working",AK22*(1+$B$16)+X23,MAX(AK22*(1+$B$16)-MIN(Y23,AK22*(1+$B$16)),0)) -> 1673263.2 | AL23: =IF(C23="Working",IF(B23=0,0,W23/B23),0) -> 0.37253324 | AM23: =IF(C23="Working",IF(B23=0,0,X23/B23),0) -> 0.40608193 | AN23: =A23 -> 5 | AO23: ='Model Inputs'!$B$22+AN23-1 -> 2030 | AP23: =IF(AND(AQ23="",AR23="",AX23="",BA23="",BC23=""),"",IF(AN23=1,(13-'Model Inputs'!$B$23)/12,1)) -> 1 | AQ23: =IF(OR(AN23<='Model Inputs'!$B$24,AR23<>"",AX23<>"",BA23<>"",BC23<>""),'Model Inputs'!$B$25*(1+'Model Inputs'!$B$31)^(AN23-1),"") -> 300000 | AS23: =IF(AP23="","",IF(AR23="",AQ23,AR23)) -> 300000 | AT23: =IF(AS23="","",AP23*AS23) -> 300000 | AU23: =IF(AP23="","",IF(AN23=1,(13-'Model Inputs'!$B$23)/12*'Model Inputs'!$B$27,IF(AN23=2,'Model Inputs'!$B$27,IF(AN23<=MAX(3,'Model Inputs'!$B$30+1),'Model Inputs'!$B$27*(1+'Model Inputs'!$B$28)^(AN23-3),'Model Inputs'!$B$27*(1+'Model Inputs'!$B$28)^(MAX(3,'Model Inputs'!$B$30+1)-3)*(1+'Model Inputs'!$B$29)^(AN23-MAX(3,'Model Inputs'!$B$30+1)))))) -> 950000 | AV23: =IF(AU23="","",IF(AN23<=2,0,'Model Inputs'!$B$32*SIN(2*PI()*(AN23-3+'Model Inputs'!$B$34)/MAX(1,'Model Inputs'!$B$33)))) -> -0.10392305 | AY23: =IF(AP23="","",IF(AX23<>"",AX23,AU23*(1+IF(AW23="",AV23,AW23)))) -> 851273.1 | AZ23: =IF(AN23=1,'Model Inputs'!$B$26,"") | BA23: 0 | BB23: =IF(AND(AS23="",BJ23="",AZ23="",BA23="",BC23="",BD23=""),"",IF(BD23<>"",BD23,IF(BC23<>"",BC23,AT23+IF(BJ23="",0,BJ23)+IF(AZ23="",0,AZ23)+IF(BA23="",0,BA23)))) -> 953837.51 | BD23: =IF(AND(BF23="",BG23="",BE22="",BE21=""),"",IF(BF23<>"",BF23,IF(AT23="",0,AT23))+0.75*IF(BE22<>"",BE22,IF(AY22="",0,AY22))+0.25*IF(BE21<>"",BE21,IF(AY21="",0,AY21))+IF(BG23<>"",BG23,IF(AZ23="",0,AZ23)+IF(BA23="",0,BA23))) | BJ23: =IF(AP23="","",0.75*IF(AY22="",0,AY22)+0.25*IF(AY21="",0,AY21)) -> 653837.51 | BK23: =IF(AP23="","",IF(AY23="",0,AY23)+0.25*IF(AY22="",0,AY22)) -> 1031718.9 | BL23: 78000 | BM23: 50000
A24: 6 | B24: =IF(BB24="","",BB24) -> 1118900.7 | C24: =IF(B24="","Retired","Working") -> Working | D24: =IF(OR(C24="Retired",B24=""),0,MIN(B24,'Tax Assumptions'!$B$19)) -> 24500 | E24: 0 | F24: 0 | G24: =IF(C24="Working",MAX(B24-D24-E24-'Tax Assumptions'!$B$8,0),0) -> 1078300.7 | H24: =IF(G24=0,0,LOOKUP(G24,'Tax Assumptions'!$F$9:$F$15,'Tax Assumptions'!$I$9:$I$15)+(G24-LOOKUP(G24,'Tax Assumptions'!$F$9:$F$15,'Tax Assumptions'!$F$9:$F$15))*LOOKUP(G24,'Tax Assumptions'!$F$9:$F$15,'Tax Assumptions'!$H$9:$H$15)) -> 354928.5 | I24: =IF(C24="Working",MIN(MAX(B24-E24,0),'Tax Assumptions'!$B$11)*'Tax Assumptions'!$B$10,0) -> 11439 | J24: =IF(C24="Working",MAX(B24-E24,0)*'Tax Assumptions'!$B$12,0) -> 16224.06 | K24: =IF(C24="Working",MAX(MAX(B24-E24,0)-'Tax Assumptions'!$B$14,0)*'Tax Assumptions'!$B$13,0) -> 8270.106 | L24: =IF(C24="Working",MIN(B24*'Tax Assumptions'!$B$15,'Tax Assumptions'!$B$16),0) -> 411.91 | M24: =IF(C24="Working",MIN(B24*'Tax Assumptions'!$B$17,'Tax Assumptions'!$B$18),0) -> 31.2 | N24: =IF(C24="Working",MAX(B24-D24-'Tax Assumptions'!$B$9,0),0) -> 1086400.7 | O24: =IF(N24=0,0,LOOKUP(N24,'Tax Assumptions'!$K$9:$K$17,'Tax Assumptions'!$N$9:$N$17)+(N24-LOOKUP(N24,'Tax Assumptions'!$K$9:$K$17,'Tax Assumptions'!$K$9:$K$17))*LOOKUP(N24,'Tax Assumptions'!$K$9:$K$17,'Tax Assumptions'!$M$9:$M$17)) -> 72051.719 | P24: =IF(N24=0,0,LOOKUP(N24,'Tax Assumptions'!$P$9:$P$12,'Tax Assumptions'!$S$9:$S$12)+(N24-LOOKUP(N24,'Tax Assumptions'!$P$9:$P$12,'Tax Assumptions'!$P$9:$P$12))*LOOKUP(N24,'Tax Assumptions'!$P$9:$P$12,'Tax Assumptions'!$R$9:$R$12)) -> 41984.06 | Q24: =H24+I24+J24+K24+L24+M24+O24+P24 -> 505340.55 | R24: =IF(C24="Working",B24-D24-E24-F24-Q24,0) -> 589060.11 | S24: =IF(C24="Working",IF(BL24="","",BL24*(1+'Model Inputs'!$B$35)^(AN24-1)),"") -> 92741.926 | T24: =IF(C24="Working",IF(BM24="","",BM24*(1+'Model Inputs'!$B$36)^(AN24-1)),"") -> 57963.704 | U24: =IF(C24="Working",R24-S24-T24,0) -> 438354.49 | V24: =IF(C24="Working",MIN(MAX(U24,0),'Tax Assumptions'!$B$20),0) -> 7500 | W24: =IF(C24="Working",U24-V24,0) -> 430854.49 | X24: =IF(C24="Working",W24+V24+D24+E24,0) -> 462854.49 | Y24: =IF(C24="Retired",$B$13,0) -> 0 | Z24: =AA24+AB24+AC24+AD24 -> 0 | AA24: =IF(C24="Retired",MIN(Y24,((AE23)*(1+$B$15)+IF(C24="Working",W24,0))),0) -> 0 | AB24: =IF(C24="Retired",MIN(MAX(Y24-AA24,0),((AF23)*(1+$B$15)+IF(C24="Working",D24,0))),0) -> 0 | AC24: =IF(C24="Retired",MIN(MAX(Y24-AA24-AB24,0),((AG23)*(1+$B$15)+IF(C24="Working",V24,0))),0) -> 0 | AD24: =IF(C24="Retired",MIN(MAX(Y24-AA24-AB24-AC24,0),((AH23)*(1+$B$15)+IF(C24="Working",E24,0))),0) -> 0 | AE24: =MAX(((AE23)*(1+$B$15)+IF(C24="Working",W24,0))-AA24,0) -> 1943183.1 | AF24: =MAX(((AF23)*(1+$B$15)+IF(C24="Working",D24,0))-AB24,0) -> 170895.3 | AG24: =MAX(((AG23)*(1+$B$15)+IF(C24="Working",V24,0))-AC24,0) -> 52314.889 | AH24: =MAX(((AH23)*(1+$B$15)+IF(C24="Working",E24,0))-AD24,0) -> 0 | AI24: =AE24+AF24+AG24+AH24 -> 2166393.3 | AJ24: =IF(C24="Working",AJ23+X24,MAX(AJ23-MIN(Y24,AJ23),0)) -> 1889629.8 | AK24: =IF(C24="Working",AK23*(1+$B$16)+X24,MAX(AK23*(1+$B$16)-MIN(Y24,AK23*(1+$B$16)),0)) -> 2269978.7 | AL24: =IF(C24="Working",IF(B24=0,0,W24/B24),0) -> 0.38506947 | AM24: =IF(C24="Working",IF(B24=0,0,X24/B24),0) -> 0.41366897 | AN24: =A24 -> 6 | AO24: ='Model Inputs'!$B$22+AN24-1 -> 2031 | AP24: =IF(AND(AQ24="",AR24="",AX24="",BA24="",BC24=""),"",IF(AN24=1,(13-'Model Inputs'!$B$23)/12,1)) -> 1 | AQ24: =IF(OR(AN24<='Model Inputs'!$B$24,AR24<>"",AX24<>"",BA24<>"",BC24<>""),'Model Inputs'!$B$25*(1+'Model Inputs'!$B$31)^(AN24-1),"") -> 300000 | AS24: =IF(AP24="","",IF(AR24="",AQ24,AR24)) -> 300000 | AT24: =IF(AS24="","",AP24*AS24) -> 300000 | AU24: =IF(AP24="","",IF(AN24=1,(13-'Model Inputs'!$B$23)/12*'Model Inputs'!$B$27,IF(AN24=2,'Model Inputs'!$B$27,IF(AN24<=MAX(3,'Model Inputs'!$B$30+1),'Model Inputs'!$B$27*(1+'Model Inputs'!$B$28)^(AN24-3),'Model Inputs'!$B$27*(1+'Model Inputs'!$B$28)^(MAX(3,'Model Inputs'!$B$30+1)-3)*(1+'Model Inputs'!$B$29)^(AN24-MAX(3,'Model Inputs'!$B$30+1)))))) -> 1207333.6 | AV24: =IF(AU24="","",IF(AN24<=2,0,'Model Inputs'!$B$32*SIN(2*PI()*(AN24-3+'Model Inputs'!$B$34)/MAX(1,'Model Inputs'!$B$33)))) -> -2.9391523e-17 | AY24: =IF(AP24="","",IF(AX24<>"",AX24,AU24*(1+IF(AW24="",AV24,AW24)))) -> 1207333.6 | AZ24: =IF(AN24=1,'Model Inputs'!$B$26,"") | BA24: 0 | BB24: =IF(AND(AS24="",BJ24="",AZ24="",BA24="",BC24="",BD24=""),"",IF(BD24<>"",BD24,IF(BC24<>"",BC24,AT24+IF(BJ24="",0,BJ24)+IF(AZ24="",0,AZ24)+IF(BA24="",0,BA24)))) -> 1118900.7 | BD24: =IF(AND(BF24="",BG24="",BE23="",BE22=""),"",IF(BF24<>"",BF24,IF(AT24="",0,AT24))+0.75*IF(BE23<>"",BE23,IF(AY23="",0,AY23))+0.25*IF(BE22<>"",BE22,IF(AY22="",0,AY22))+IF(BG24<>"",BG24,IF(AZ24="",0,AZ24)+IF(BA24="",0,BA24))) | BJ24: =IF(AP24="","",0.75*IF(AY23="",0,AY23)+0.25*IF(AY22="",0,AY22)) -> 818900.67 | BK24: =IF(AP24="","",IF(AY24="",0,AY24)+0.25*IF(AY23="",0,AY23)) -> 1420151.8 | BL24: 80000 | BM24: 50000
A25: 7 | B25: =IF(BB25="","",BB25) -> 1418318.4 | C25: =IF(B25="","Retired","Working") -> Working | D25: =IF(OR(C25="Retired",B25=""),0,MIN(B25,'Tax Assumptions'!$B$19)) -> 24500 | E25: 0 | F25: 0 | G25: =IF(C25="Working",MAX(B25-D25-E25-'Tax Assumptions'!$B$8,0),0) -> 1377718.4 | H25: =IF(G25=0,0,LOOKUP(G25,'Tax Assumptions'!$F$9:$F$15,'Tax Assumptions'!$I$9:$I$15)+(G25-LOOKUP(G25,'Tax Assumptions'!$F$9:$F$15,'Tax Assumptions'!$F$9:$F$15))*LOOKUP(G25,'Tax Assumptions'!$F$9:$F$15,'Tax Assumptions'!$H$9:$H$15)) -> 465713.08 | I25: =IF(C25="Working",MIN(MAX(B25-E25,0),'Tax Assumptions'!$B$11)*'Tax Assumptions'!$B$10,0) -> 11439 | J25: =IF(C25="Working",MAX(B25-E25,0)*'Tax Assumptions'!$B$12,0) -> 20565.618 | K25: =IF(C25="Working",MAX(MAX(B25-E25,0)-'Tax Assumptions'!$B$14,0)*'Tax Assumptions'!$B$13,0) -> 10964.866 | L25: =IF(C25="Working",MIN(B25*'Tax Assumptions'!$B$15,'Tax Assumptions'!$B$16),0) -> 411.91 | M25: =IF(C25="Working",MIN(B25*'Tax Assumptions'!$B$17,'Tax Assumptions'!$B$18),0) -> 31.2 | N25: =IF(C25="Working",MAX(B25-D25-'Tax Assumptions'!$B$9,0),0) -> 1385818.4 | O25: =IF(N25=0,0,LOOKUP(N25,'Tax Assumptions'!$K$9:$K$17,'Tax Assumptions'!$N$9:$N$17)+(N25-LOOKUP(N25,'Tax Assumptions'!$K$9:$K$17,'Tax Assumptions'!$K$9:$K$17))*LOOKUP(N25,'Tax Assumptions'!$K$9:$K$17,'Tax Assumptions'!$M$9:$M$17)) -> 100945.54 | P25: =IF(N25=0,0,LOOKUP(N25,'Tax Assumptions'!$P$9:$P$12,'Tax Assumptions'!$S$9:$S$12)+(N25-LOOKUP(N25,'Tax Assumptions'!$P$9:$P$12,'Tax Assumptions'!$P$9:$P$12))*LOOKUP(N25,'Tax Assumptions'!$P$9:$P$12,'Tax Assumptions'!$R$9:$R$12)) -> 53589.493 | Q25: =H25+I25+J25+K25+L25+M25+O25+P25 -> 663660.7 | R25: =IF(C25="Working",B25-D25-E25-F25-Q25,0) -> 730157.75 | S25: =IF(C25="Working",IF(BL25="","",BL25*(1+'Model Inputs'!$B$35)^(AN25-1)),"") -> 95524.184 | T25: =IF(C25="Working",IF(BM25="","",BM25*(1+'Model Inputs'!$B$36)^(AN25-1)),"") -> 59702.615 | U25: =IF(C25="Working",R25-S25-T25,0) -> 574930.95 | V25: =IF(C25="Working",MIN(MAX(U25,0),'Tax Assumptions'!$B$20),0) -> 7500 | W25: =IF(C25="Working",U25-V25,0) -> 567430.95 | X25: =IF(C25="Working",W25+V25+D25+E25,0) -> 599430.95 | Y25: =IF(C25="Retired",$B$13,0) -> 0 | Z25: =AA25+AB25+AC25+AD25 -> 0 | AA25: =IF(C25="Retired",MIN(Y25,((AE24)*(1+$B$15)+IF(C25="Working",W25,0))),0) -> 0 | AB25: =IF(C25="Retired",MIN(MAX(Y25-AA25,0),((AF24)*(1+$B$15)+IF(C25="Working",D25,0))),0) -> 0 | AC25: =IF(C25="Retired",MIN(MAX(Y25-AA25-AB25,0),((AG24)*(1+$B$15)+IF(C25="Working",V25,0))),0) -> 0 | AD25: =IF(C25="Retired",MIN(MAX(Y25-AA25-AB25-AC25,0),((AH24)*(1+$B$15)+IF(C25="Working",E25,0))),0) -> 0 | AE25: =MAX(((AE24)*(1+$B$15)+IF(C25="Working",W25,0))-AA25,0) -> 2627205 | AF25: =MAX(((AF24)*(1+$B$15)+IF(C25="Working",D25,0))-AB25,0) -> 205649.02 | AG25: =MAX(((AG24)*(1+$B$15)+IF(C25="Working",V25,0))-AC25,0) -> 62953.782 | AH25: =MAX(((AH24)*(1+$B$15)+IF(C25="Working",E25,0))-AD25,0) -> 0 | AI25: =AE25+AF25+AG25+AH25 -> 2895807.8 | AJ25: =IF(C25="Working",AJ24+X25,MAX(AJ24-MIN(Y25,AJ24),0)) -> 2489060.7 | AK25: =IF(C25="Working",AK24*(1+$B$16)+X25,MAX(AK24*(1+$B$16)-MIN(Y25,AK24*(1+$B$16)),0)) -> 3051008 | AL25: =IF(C25="Working",IF(B25=0,0,W25/B25),0) -> 0.40007303 | AM25: =IF(C25="Working",IF(B25=0,0,X25/B25),0) -> 0.42263495 | AN25: =A25 -> 7 | AO25: ='Model Inputs'!$B$22+AN25-1 -> 2032 | AP25: =IF(AND(AQ25="",AR25="",AX25="",BA25="",BC25=""),"",IF(AN25=1,(13-'Model Inputs'!$B$23)/12,1)) -> 1 | AQ25: =IF(OR(AN25<='Model Inputs'!$B$24,AR25<>"",AX25<>"",BA25<>"",BC25<>""),'Model Inputs'!$B$25*(1+'Model Inputs'!$B$31)^(AN25-1),"") -> 300000 | AS25: =IF(AP25="","",IF(AR25="",AQ25,AR25)) -> 300000 | AT25: =IF(AS25="","",AP25*AS25) -> 300000 | AU25: =IF(AP25="","",IF(AN25=1,(13-'Model Inputs'!$B$23)/12*'Model Inputs'!$B$27,IF(AN25=2,'Model Inputs'!$B$27,IF(AN25<=MAX(3,'Model Inputs'!$B$30+1),'Model Inputs'!$B$27*(1+'Model Inputs'!$B$28)^(AN25-3),'Model Inputs'!$B$27*(1+'Model Inputs'!$B$28)^(MAX(3,'Model Inputs'!$B$30+1)-3)*(1+'Model Inputs'!$B$29)^(AN25-MAX(3,'Model Inputs'!$B$30+1)))))) -> 1534373 | AV25: =IF(AU25="","",IF(AN25<=2,0,'Model Inputs'!$B$32*SIN(2*PI()*(AN25-3+'Model Inputs'!$B$34)/MAX(1,'Model Inputs'!$B$33)))) -> 0.10392305 | AY25: =IF(AP25="","",IF(AX25<>"",AX25,AU25*(1+IF(AW25="",AV25,AW25)))) -> 1693829.7 | AZ25: =IF(AN25=1,'Model Inputs'!$B$26,"") | BA25: 0 | BB25: =IF(AND(AS25="",BJ25="",AZ25="",BA25="",BC25="",BD25=""),"",IF(BD25<>"",BD25,IF(BC25<>"",BC25,AT25+IF(BJ25="",0,BJ25)+IF(AZ25="",0,AZ25)+IF(BA25="",0,BA25)))) -> 1418318.4 | BD25: =IF(AND(BF25="",BG25="",BE24="",BE23=""),"",IF(BF25<>"",BF25,IF(AT25="",0,AT25))+0.75*IF(BE24<>"",BE24,IF(AY24="",0,AY24))+0.25*IF(BE23<>"",BE23,IF(AY23="",0,AY23))+IF(BG25<>"",BG25,IF(AZ25="",0,AZ25)+IF(BA25="",0,BA25))) | BJ25: =IF(AP25="","",0.75*IF(AY24="",0,AY24)+0.25*IF(AY23="",0,AY23)) -> 1118318.4 | BK25: =IF(AP25="","",IF(AY25="",0,AY25)+0.25*IF(AY24="",0,AY24)) -> 1995663.1 | BL25: 80000 | BM25: 50000
A26: 8 | B26: =IF(BB26="","",BB26) -> 1872205.7 | C26: =IF(B26="","Retired","Working") -> Working | D26: =IF(OR(C26="Retired",B26=""),0,MIN(B26,'Tax Assumptions'!$B$19)) -> 24500 | E26: 0 | F26: 0 | G26: =IF(C26="Working",MAX(B26-D26-E26-'Tax Assumptions'!$B$8,0),0) -> 1831605.7 | H26: =IF(G26=0,0,LOOKUP(G26,'Tax Assumptions'!$F$9:$F$15,'Tax Assumptions'!$I$9:$I$15)+(G26-LOOKUP(G26,'Tax Assumptions'!$F$9:$F$15,'Tax Assumptions'!$F$9:$F$15))*LOOKUP(G26,'Tax Assumptions'!$F$9:$F$15,'Tax Assumptions'!$H$9:$H$15)) -> 633651.35 | I26: =IF(C26="Working",MIN(MAX(B26-E26,0),'Tax Assumptions'!$B$11)*'Tax Assumptions'!$B$10,0) -> 11439 | J26: =IF(C26="Working",MAX(B26-E26,0)*'Tax Assumptions'!$B$12,0) -> 27146.982 | K26: =IF(C26="Working",MAX(MAX(B26-E26,0)-'Tax Assumptions'!$B$14,0)*'Tax Assumptions'!$B$13,0) -> 15049.851 | L26: =IF(C26="Working",MIN(B26*'Tax Assumptions'!$B$15,'Tax Assumptions'!$B$16),0) -> 411.91 | M26: =IF(C26="Working",MIN(B26*'Tax Assumptions'!$B$17,'Tax Assumptions'!$B$18),0) -> 31.2 | N26: =IF(C26="Working",MAX(B26-D26-'Tax Assumptions'!$B$9,0),0) -> 1839705.7 | O26: =IF(N26=0,0,LOOKUP(N26,'Tax Assumptions'!$K$9:$K$17,'Tax Assumptions'!$N$9:$N$17)+(N26-LOOKUP(N26,'Tax Assumptions'!$K$9:$K$17,'Tax Assumptions'!$K$9:$K$17))*LOOKUP(N26,'Tax Assumptions'!$K$9:$K$17,'Tax Assumptions'!$M$9:$M$17)) -> 144745.65 | P26: =IF(N26=0,0,LOOKUP(N26,'Tax Assumptions'!$P$9:$P$12,'Tax Assumptions'!$S$9:$S$12)+(N26-LOOKUP(N26,'Tax Assumptions'!$P$9:$P$12,'Tax Assumptions'!$P$9:$P$12))*LOOKUP(N26,'Tax Assumptions'!$P$9:$P$12,'Tax Assumptions'!$R$9:$R$12)) -> 71182.162 | Q26: =H26+I26+J26+K26+L26+M26+O26+P26 -> 903658.1 | R26: =IF(C26="Working",B26-D26-E26-F26-Q26,0) -> 944047.56 | S26: =IF(C26="Working",IF(BL26="","",BL26*(1+'Model Inputs'!$B$35)^(AN26-1)),"") -> 98389.909 | T26: =IF(C26="Working",IF(BM26="","",BM26*(1+'Model Inputs'!$B$36)^(AN26-1)),"") -> 61493.693 | U26: =IF(C26="Working",R26-S26-T26,0) -> 784163.96 | V26: =IF(C26="Working",MIN(MAX(U26,0),'Tax Assumptions'!$B$20),0) -> 7500 | W26: =IF(C26="Working",U26-V26,0) -> 776663.96 | X26: =IF(C26="Working",W26+V26+D26+E26,0) -> 808663.96 | Y26: =IF(C26="Retired",$B$13,0) -> 0 | Z26: =AA26+AB26+AC26+AD26 -> 0 | AA26: =IF(C26="Retired",MIN(Y26,((AE25)*(1+$B$15)+IF(C26="Working",W26,0))),0) -> 0 | AB26: =IF(C26="Retired",MIN(MAX(Y26-AA26,0),((AF25)*(1+$B$15)+IF(C26="Working",D26,0))),0) -> 0 | AC26: =IF(C26="Retired",MIN(MAX(Y26-AA26-AB26,0),((AG25)*(1+$B$15)+IF(C26="Working",V26,0))),0) -> 0 | AD26: =IF(C26="Retired",MIN(MAX(Y26-AA26-AB26-AC26,0),((AH25)*(1+$B$15)+IF(C26="Working",E26,0))),0) -> 0 | AE26: =MAX(((AE25)*(1+$B$15)+IF(C26="Working",W26,0))-AA26,0) -> 3561501.3 | AF26: =MAX(((AF25)*(1+$B$15)+IF(C26="Working",D26,0))-AB26,0) -> 242487.96 | AG26: =MAX(((AG25)*(1+$B$15)+IF(C26="Working",V26,0))-AC26,0) -> 74231.009 | AH26: =MAX(((AH25)*(1+$B$15)+IF(C26="Working",E26,0))-AD26,0) -> 0 | AI26: =AE26+AF26+AG26+AH26 -> 3878220.2 | AJ26: =IF(C26="Working",AJ25+X26,MAX(AJ25-MIN(Y26,AJ25),0)) -> 3297724.7 | AK26: =IF(C26="Working",AK25*(1+$B$16)+X26,MAX(AK25*(1+$B$16)-MIN(Y26,AK25*(1+$B$16)),0)) -> 4103752.6 | AL26: =IF(C26="Working",IF(B26=0,0,W26/B26),0) -> 0.41483902 | AM26: =IF(C26="Working",IF(B26=0,0,X26/B26),0) -> 0.43193116 | AN26: =A26 -> 8 | AO26: ='Model Inputs'!$B$22+AN26-1 -> 2033 | AP26: =IF(AND(AQ26="",AR26="",AX26="",BA26="",BC26=""),"",IF(AN26=1,(13-'Model Inputs'!$B$23)/12,1)) -> 1 | AQ26: =IF(OR(AN26<='Model Inputs'!$B$24,AR26<>"",AX26<>"",BA26<>"",BC26<>""),'Model Inputs'!$B$25*(1+'Model Inputs'!$B$31)^(AN26-1),"") -> 300000 | AS26: =IF(AP26="","",IF(AR26="",AQ26,AR26)) -> 300000 | AT26: =IF(AS26="","",AP26*AS26) -> 300000 | AU26: =IF(AP26="","",IF(AN26=1,(13-'Model Inputs'!$B$23)/12*'Model Inputs'!$B$27,IF(AN26=2,'Model Inputs'!$B$27,IF(AN26<=MAX(3,'Model Inputs'!$B$30+1),'Model Inputs'!$B$27*(1+'Model Inputs'!$B$28)^(AN26-3),'Model Inputs'!$B$27*(1+'Model Inputs'!$B$28)^(MAX(3,'Model Inputs'!$B$30+1)-3)*(1+'Model Inputs'!$B$29)^(AN26-MAX(3,'Model Inputs'!$B$30+1)))))) -> 1950000 | AV26: =IF(AU26="","",IF(AN26<=2,0,'Model Inputs'!$B$32*SIN(2*PI()*(AN26-3+'Model Inputs'!$B$34)/MAX(1,'Model Inputs'!$B$33)))) -> -0.10392305 | AY26: =IF(AP26="","",IF(AX26<>"",AX26,AU26*(1+IF(AW26="",AV26,AW26)))) -> 1747350.1 | AZ26: =IF(AN26=1,'Model Inputs'!$B$26,"") | BA26: 0 | BB26: =IF(AND(AS26="",BJ26="",AZ26="",BA26="",BC26="",BD26=""),"",IF(BD26<>"",BD26,IF(BC26<>"",BC26,AT26+IF(BJ26="",0,BJ26)+IF(AZ26="",0,AZ26)+IF(BA26="",0,BA26)))) -> 1872205.7 | BD26: =IF(AND(BF26="",BG26="",BE25="",BE24=""),"",IF(BF26<>"",BF26,IF(AT26="",0,AT26))+0.75*IF(BE25<>"",BE25,IF(AY25="",0,AY25))+0.25*IF(BE24<>"",BE24,IF(AY24="",0,AY24))+IF(BG26<>"",BG26,IF(AZ26="",0,AZ26)+IF(BA26="",0,BA26))) | BJ26: =IF(AP26="","",0.75*IF(AY25="",0,AY25)+0.25*IF(AY24="",0,AY24)) -> 1572205.7 | BK26: =IF(AP26="","",IF(AY26="",0,AY26)+0.25*IF(AY25="",0,AY25)) -> 2170807.5 | BL26: 80000 | BM26: 50000
